Workbook
Name Dt: Inputs!$C$32
Name E_1000: Inputs!$C$36
Name E_640: Inputs!$C$35
Name GamP: Inputs!$C$33
Name GamS: Inputs!$C$34
Name H_Z1: Inputs!$C$11
Name H_Z2: Inputs!$C$12
Name Kt: Inputs!$C$31
Name Kv: Inputs!$C$30
Name N_dn1: Inputs!$C$45
Name N_dn2: Inputs!$C$47
Name N_up1: Inputs!$C$44
Name N_up2: Inputs!$C$46
Name P_15: Inputs!$C$26
Name P_18: Inputs!$C$25
Name P_25: Inputs!$C$28
Name P_28: Inputs!$C$27
Name SPD: Inputs!$D$39:$H$39
Name T_123: Inputs!$D$40:$H$40
Name TUtarget: Inputs!$C$37

Sheet Inputs
A1: ИСХОДНЫЕ ДАННЫЕ И ПАРАМЕТРЫ МЕТОДИКИ (ГОСТ Р 52941-2008, прил. А)
B3: Высота надземного этажа, м | C3: 3.9 | D3: Подтверждено пользователем, 30.09.2026
B4: Высота подземного этажа, м | C4: 3.6 | D4: Подтверждено пользователем, 30.09.2026
B5: Отметка пола верхнего уровня холла 1-го этажа, м | C5: 6 | D5: Подтверждено пользователем, 30.09.2026
B6: Верхняя остановка зоны 1 (этаж) | C6: 8 | D6: Подтверждено пользователем, 30.09.2026
B7: Верхняя остановка зоны 2 (этаж) | C7: 31 | D7: Подтверждено пользователем, 30.09.2026
B8: Нижний жилой этаж | C8: 2 | D8: Подтверждено пользователем, 30.09.2026
B9: Межэтажных расстояний до верхней остановки З1 | C9: =C6-C8 -> 6
B10: Межэтажных расстояний до верхней остановки З2 (вкл. тех. этаж) | C10: =C7-C8 -> 29
B11: Высота подъема зоны 1 H, м | C11: =C5+C9*C3+2*C4 -> 36.6
B12: Высота подъема зоны 2 H, м | C12: =C5+C10*C3+2*C4 -> 126.3
B13: Квартир всего | C13: 283 | D13: Подтверждено пользователем, 30.09.2026
B14: Квартир в группе этажей 2-10 | C14: 125 | D14: Подтверждено пользователем, 30.09.2026
B15: Этажей в группе 2-10 | C15: 9 | D15: Подтверждено пользователем, 30.09.2026
B16: Жилых этажей зоны 1 (2-7) | C16: 6 | D16: Подтверждено пользователем, 30.09.2026
B17: Жилых этажей зоны 2 (8-13, 15-31) | C17: 23 | D17: Подтверждено пользователем, 30.09.2026
B18: Квартир в зоне 1 | C18: =ROUND(C14*C16/C15,0) -> 83
B19: Квартир в зоне 2 | C19: =C13-C18 -> 200
B20: Жителей на квартиру, чел. | C20: 3 | D20: Допущение: верхняя граница диапазона 1,2-3,0 чел./кв. по ГОСТ Р 52941-2008
B21: Население зоны 1, чел. | C21: =C18*C20 -> 249
B22: Население зоны 2, чел. | C22: =C19*C20 -> 600
B23: Расчетный пик (верхняя граница ГОСТ Р 52941-2008) | C23: 0.08 | D23: Диапазон 4-8 %; по прил. Д СП 267 — 3-5 %
B24: Расчетный пик для сопоставления (СП 267) | C24: 0.05 | D24: Допущение: источник не предоставлен пользователем
B25: Pчас зоны 1 при пике 8 %, чел./ч | C25: =C21*C23*12 -> 239.04
B26: Pчас зоны 1 при пике 5 %, чел./ч | C26: =C21*C24*12 -> 149.4
B27: Pчас зоны 2 при пике 8 %, чел./ч | C27: =C22*C23*12 -> 576
B28: Pчас зоны 2 при пике 5 %, чел./ч | C28: =C22*C24*12 -> 360
B30: Kв (коэф. вероятной высоты подъема) | C30: 0.8 | D30: Диапазон 0,7-0,9 по прил. А ГОСТ Р 52941-2008
B31: Kt (коэф. доп. задержек) | C31: 1.05 | D31: Диапазон 1,05-1,10 по п. А.2.6 г прил. А ГОСТ Р 52941-2008; принята нижняя граница
B32: Δt (вход/выход одного пассажира), с | C32: 1.5 | D32: Дверной проем менее 1000 мм: диапазон 1,5-2,0 с
B33: γп (доля загрузки при подъеме) | C33: 0.8 | D33: Прил. А ГОСТ Р 52941-2008
B34: γс (доля загрузки при спуске) | C34: 0.4 | D34: Прил. А ГОСТ Р 52941-2008
B35: E 640 кг, чел. | C35: 8 | D35: Паспортная вместимость типовой кабины 630-640 кг — 8 чел.; по формуле прил. А ГОСТ Р 52941-2008 (640/75 = 8,53, округление до ближайшего целого) — 9 чел.; подтвердить паспортом лифта (лист «Допущения»)
B36: E 1000 кг, чел. | C36: =ROUNDDOWN(1000/75,0) -> 13
B37: Целевой интервал ТЗ, с | C37: 50 | D37: Предыдущая редакция ТЗ
B39: Скорость, м/с | D39: 1 | E39: 1.6 | F39: 2.5 | G39: 3.5 | H39: 4
B40: t1+t2+t3, с (середины диапазонов табл. прил. А) | D40: 13.5 | E40: 12 | F40: 14 | G40: 15 | H40: 16.5
B43: Возможные пункты назначения (для расчета числа остановок)
B44: Зона 1: N вверх (этажи 2-7) | C44: 6
B45: Зона 1: N вниз (+ паркинг -1, -2 и верхний уровень холла) | C45: 9
...

Sheet Zone1
A1: РАСЧЕТ ЗОНЫ 1 (жилые этажи 2-7; 249 чел.)
B3: Тип лифта | C3: E, чел. | D3: P вверх | E3: P вниз | F3: Nост
B4: 640 кг | C4: =E_640 -> 8 | D4: =ROUND(GamP*C4,0) -> 6 | E4: =ROUND(GamS*C4,0) -> 3 | F4: =N_up1*(1-(1-1/N_up1)^D4)+N_dn1*(1-(1-1/N_dn1)^E4) -> 6.6696245
B5: 1000 кг (пожарный) | C5: =E_1000 -> 13 | D5: =ROUND(GamP*C5,0) -> 10 | E5: =ROUND(GamS*C5,0) -> 5 | F5: =N_up1*(1-(1-1/N_up1)^D5)+N_dn1*(1-(1-1/N_dn1)^E5) -> 9.0366059
B7: Конфигурация | C7: V 640, м/с | D7: V 1000, м/с | E7: n 640 | F7: n 1000 | G7: T 640, с | H7: T 1000, с | I7: ΣPл, чел./ч | J7: Kр при 8 % | K7: Kр при 5 % | L7: tи, с | M7: Уровень комфортности | N7: H/V 640, с | O7: H/V 1000, с
B8: 1×640 + 1×1000 (пожарный) — база | C8: 1.6 | D8: 1.6 | E8: 1 | F8: 1 | G8: =(2*Kv*H_Z1/C8+$F$4*INDEX(T_123,MATCH(C8,SPD,0))+(GamP+GamS)*E_640*Dt)*Kt -> 137.58727 | H8: =(2*Kv*H_Z1/D8+$F$5*INDEX(T_123,MATCH(D8,SPD,0))+(GamP+GamS)*E_1000*Dt)*Kt -> 176.86123 | I8: =E8*3600*(GamP+GamS)*E_640/G8+F8*3600*(GamP+GamS)*E_1000/H8 -> 568.72311 | J8: =P_18/I8 -> 0.42030998 | K8: =P_15/I8 -> 0.26269374 | L8: =1/(E8/G8+F8/H8) -> 77.385816 | M8: =IF(L8<=60,"отличный",IF(L8<=80,"хороший",IF(L8<=100,"удовлетворительный",">100 с"))) -> хороший | N8: =H_Z1/C8 -> 22.875 | O8: =H_Z1/D8 -> 22.875
B9: то же на скорости 2,5 м/с | C9: 2.5 | D9: 2.5 | E9: 1 | F9: 1 | G9: =(2*Kv*H_Z1/C9+$F$4*INDEX(T_123,MATCH(C9,SPD,0))+(GamP+GamS)*E_640*Dt)*Kt -> 137.75868 | H9: =(2*Kv*H_Z1/D9+$F$5*INDEX(T_123,MATCH(D9,SPD,0))+(GamP+GamS)*E_1000*Dt)*Kt -> 182.00331 | I9: =E9*3600*(GamP+GamS)*E_640/G9+F9*3600*(GamP+GamS)*E_1000/H9 -> 559.43931 | J9: =P_18/I9 -> 0.42728496 | K9: =P_15/I9 -> 0.2670531 | L9: =1/(E9/G9+F9/H9) -> 78.409993 | M9: =IF(L9<=60,"отличный",IF(L9<=80,"хороший",IF(L9<=100,"удовлетворительный",">100 с"))) -> хороший | N9: =H_Z1/C9 -> 14.64 | O9: =H_Z1/D9 -> 14.64
B10: то же на скорости 4,0 м/с | C10: 4 | D10: 4 | E10: 1 | F10: 1 | G10: =(2*Kv*H_Z1/C10+$F$4*INDEX(T_123,MATCH(C10,SPD,0))+(GamP+GamS)*E_640*Dt)*Kt -> 146.04324 | H10: =(2*Kv*H_Z1/D10+$F$5*INDEX(T_123,MATCH(D10,SPD,0))+(GamP+GamS)*E_1000*Dt)*Kt -> 196.5012 | I10: =E10*3600*(GamP+GamS)*E_640/G10+F10*3600*(GamP+GamS)*E_1000/H10 -> 522.44202 | J10: =P_18/I10 -> 0.45754359 | K10: =P_15/I10 -> 0.28596475 | L10: =1/(E10/G10+F10/H10) -> 83.777954 | M10: =IF(L10<=60,"отличный",IF(L10<=80,"хороший",IF(L10<=100,"удовлетворительный",">100 с"))) -> удовлетворительный | N10: =H_Z1/C10 -> 9.15 | O10: =H_Z1/D10 -> 9.15
B11: 2×640 + 1×1000 (пожарный) — 3 лифта, 1,6 м/с | C11: 1.6 | D11: 1.6 | E11: 2 | F11: 1 | G11: =(2*Kv*H_Z1/C11+$F$4*INDEX(T_123,MATCH(C11,SPD,0))+(GamP+GamS)*E_640*Dt)*Kt -> 137.58727 | H11: =(2*Kv*H_Z1/D11+$F$5*INDEX(T_123,MATCH(D11,SPD,0))+(GamP+GamS)*E_1000*Dt)*Kt -> 176.86123 | I11: =E11*3600*(GamP+GamS)*E_640/G11+F11*3600*(GamP+GamS)*E_1000/H11 -> 819.90914 | J11: =P_18/I11 -> 0.2915445 | K11: =P_15/I11 -> 0.18221531 | L11: =1/(E11/G11+F11/H11) -> 49.52854 | M11: =IF(L11<=60,"отличный",IF(L11<=80,"хороший",IF(L11<=100,"удовлетворительный",">100 с"))) -> отличный | N11: =H_Z1/C11 -> 22.875 | O11: =H_Z1/D11 -> 22.875
B12: 2×640 + 1×1000 (пожарный) — 3 лифта, 2,5 м/с | C12: 2.5 | D12: 2.5 | E12: 2 | F12: 1 | G12: =(2*Kv*H_Z1/C12+$F$4*INDEX(T_123,MATCH(C12,SPD,0))+(GamP+GamS)*E_640*Dt)*Kt -> 137.75868 | H12: =(2*Kv*H_Z1/D12+$F$5*INDEX(T_123,MATCH(D12,SPD,0))+(GamP+GamS)*E_1000*Dt)*Kt -> 182.00331 | I12: =E12*3600*(GamP+GamS)*E_640/G12+F12*3600*(GamP+GamS)*E_1000/H12 -> 810.31279 | J12: =P_18/I12 -> 0.29499719 | K12: =P_15/I12 -> 0.18437325 | L12: =1/(E12/G12+F12/H12) -> 49.968652 | M12: =IF(L12<=60,"отличный",IF(L12<=80,"хороший",IF(L12<=100,"удовлетворительный",">100 с"))) -> отличный | N12: =H_Z1/C12 -> 14.64 | O12: =H_Z1/D12 -> 14.64
B13: только 640 (пожарный не участвует) — справочно | C13: 1.6 | D13: 1.6 | E13: 1 | F13: 0 | G13: =(2*Kv*H_Z1/C13+$F$4*INDEX(T_123,MATCH(C13,SPD,0))+(GamP+GamS)*E_640*Dt)*Kt -> 137.58727 | H13: =(2*Kv*H_Z1/D13+$F$5*INDEX(T_123,MATCH(D13,SPD,0))+(GamP+GamS)*E_1000*Dt)*Kt -> 176.86123 | I13: =E13*3600*(GamP+GamS)*E_640/G13+F13*3600*(GamP+GamS)*E_1000/H13 -> 251.18603 | J13: =P_18/I13 -> 0.95164527 | K13: =P_15/I13 -> 0.5947783 | L13: =1/(E13/G13+F13/H13) -> 137.58727 | M13: =IF(L13<=60,"отличный",IF(L13<=80,"хороший",IF(L13<=100,"удовлетворительный",">100 с"))) -> >100 с | N13: =H_Z1/C13 -> 22.875 | O13: =H_Z1/D13 -> 22.875

Sheet Zone2
A1: РАСЧЕТ ЗОНЫ 2 (жилые этажи 8-13, 15-31; 600 чел.)
B3: Тип лифта | C3: E, чел. | D3: P вверх | E3: P вниз | F3: Nост
B4: 640 кг | C4: =E_640 -> 8 | D4: =ROUND(GamP*C4,0) -> 6 | E4: =ROUND(GamS*C4,0) -> 3 | F4: =N_up2*(1-(1-1/N_up2)^D4)+N_dn2*(1-(1-1/N_dn2)^E4) -> 8.2705164
B5: 1000 кг (пожарный) | C5: =E_1000 -> 13 | D5: =ROUND(GamP*C5,0) -> 10 | E5: =ROUND(GamS*C5,0) -> 5 | F5: =N_up2*(1-(1-1/N_up2)^D5)+N_dn2*(1-(1-1/N_dn2)^E5) -> 12.883825
B7: Конфигурация | C7: V 640, м/с | D7: V 1000, м/с | E7: n 640 | F7: n 1000 | G7: T 640, с | H7: T 1000, с | I7: ΣPл, чел./ч | J7: Kр при 8 % | K7: Kр при 5 % | L7: tи, с | M7: Уровень комфортности | N7: H/V 640, с | O7: H/V 1000, с
B8: 3×640 @2,5 + 2×1000 @2,5 | C8: 2.5 | D8: 2.5 | E8: 3 | F8: 2 | G8: =(2*Kv*H_Z2/C8+$F$4*INDEX(T_123,MATCH(C8,SPD,0))+(GamP+GamS)*E_640*Dt)*Kt -> 221.57019 | H8: =(2*Kv*H_Z2/D8+$F$5*INDEX(T_123,MATCH(D8,SPD,0))+(GamP+GamS)*E_1000*Dt)*Kt -> 298.83583 | I8: =E8*3600*(GamP+GamS)*E_640/G8+F8*3600*(GamP+GamS)*E_1000/H8 -> 843.79152 | J8: =P_28/I8 -> 0.68263308 | K8: =P_25/I8 -> 0.42664567 | L8: =1/(E8/G8+F8/H8) -> 49.425759 | M8: =IF(L8<=60,"отличный",IF(L8<=80,"хороший",IF(L8<=100,"удовлетворительный",">100 с"))) -> отличный | N8: =H_Z2/C8 -> 50.52 | O8: =H_Z2/D8 -> 50.52
B9: 3×640 @2,5 + 2×1000 @3,5 — БАЗА | C9: 2.5 | D9: 3.5 | E9: 3 | F9: 2 | G9: =(2*Kv*H_Z2/C9+$F$4*INDEX(T_123,MATCH(C9,SPD,0))+(GamP+GamS)*E_640*Dt)*Kt -> 221.57019 | H9: =(2*Kv*H_Z2/D9+$F$5*INDEX(T_123,MATCH(D9,SPD,0))+(GamP+GamS)*E_1000*Dt)*Kt -> 288.11425 | I9: =E9*3600*(GamP+GamS)*E_640/G9+F9*3600*(GamP+GamS)*E_1000/H9 -> 857.77833 | J9: =P_28/I9 -> 0.67150216 | K9: =P_25/I9 -> 0.41968885 | L9: =1/(E9/G9+F9/H9) -> 48.824744 | M9: =IF(L9<=60,"отличный",IF(L9<=80,"хороший",IF(L9<=100,"удовлетворительный",">100 с"))) -> отличный | N9: =H_Z2/C9 -> 50.52 | O9: =H_Z2/D9 -> 36.085714
B10: 3×640 @3,5 + 2×1000 @3,5 | C10: 3.5 | D10: 3.5 | E10: 3 | F10: 2 | G10: =(2*Kv*H_Z2/C10+$F$4*INDEX(T_123,MATCH(C10,SPD,0))+(GamP+GamS)*E_640*Dt)*Kt -> 206.00463 | H10: =(2*Kv*H_Z2/D10+$F$5*INDEX(T_123,MATCH(D10,SPD,0))+(GamP+GamS)*E_1000*Dt)*Kt -> 288.11425 | I10: =E10*3600*(GamP+GamS)*E_640/G10+F10*3600*(GamP+GamS)*E_1000/H10 -> 893.135 | J10: =P_28/I10 -> 0.6449193 | K10: =P_25/I10 -> 0.40307456 | L10: =1/(E10/G10+F10/H10) -> 46.50196 | M10: =IF(L10<=60,"отличный",IF(L10<=80,"хороший",IF(L10<=100,"удовлетворительный",">100 с"))) -> отличный | N10: =H_Z2/C10 -> 36.085714 | O10: =H_Z2/D10 -> 36.085714
B11: 3×640 @2,5 + 2×1000 @4,0 | C11: 2.5 | D11: 4 | E11: 3 | F11: 2 | G11: =(2*Kv*H_Z2/C11+$F$4*INDEX(T_123,MATCH(C11,SPD,0))+(GamP+GamS)*E_640*Dt)*Kt -> 221.57019 | H11: =(2*Kv*H_Z2/D11+$F$5*INDEX(T_123,MATCH(D11,SPD,0))+(GamP+GamS)*E_1000*Dt)*Kt -> 300.82828 | I11: =E11*3600*(GamP+GamS)*E_640/G11+F11*3600*(GamP+GamS)*E_1000/H11 -> 841.30214 | J11: =P_28/I11 -> 0.68465296 | K11: =P_25/I11 -> 0.4279081 | L11: =1/(E11/G11+F11/H11) -> 49.534282 | M11: =IF(L11<=60,"отличный",IF(L11<=80,"хороший",IF(L11<=100,"удовлетворительный",">100 с"))) -> отличный | N11: =H_Z2/C11 -> 50.52 | O11: =H_Z2/D11 -> 31.575
B12: 3×640 @4,0 + 2×1000 @4,0 | C12: 4 | D12: 4 | E12: 3 | F12: 2 | G12: =(2*Kv*H_Z2/C12+$F$4*INDEX(T_123,MATCH(C12,SPD,0))+(GamP+GamS)*E_640*Dt)*Kt -> 211.4527 | H12: =(2*Kv*H_Z2/D12+$F$5*INDEX(T_123,MATCH(D12,SPD,0))+(GamP+GamS)*E_1000*Dt)*Kt -> 300.82828 | I12: =E12*3600*(GamP+GamS)*E_640/G12+F12*3600*(GamP+GamS)*E_1000/H12 -> 863.69159 | J12: =P_28/I12 -> 0.66690472 | K12: =P_25/I12 -> 0.41681545 | L12: =1/(E12/G12+F12/H12) -> 47.99413 | M12: =IF(L12<=60,"отличный",IF(L12<=80,"хороший",IF(L12<=100,"удовлетворительный",">100 с"))) -> отличный | N12: =H_Z2/C12 -> 31.575 | O12: =H_Z2/D12 -> 31.575
B13: справочно: 3×640 @2,5 (пожарные не участвуют) | C13: 2.5 | D13: 2.5 | E13: 3 | F13: 0 | G13: =(2*Kv*H_Z2/C13+$F$4*INDEX(T_123,MATCH(C13,SPD,0))+(GamP+GamS)*E_640*Dt)*Kt -> 221.57019 | H13: =(2*Kv*H_Z2/D13+$F$5*INDEX(T_123,MATCH(D13,SPD,0))+(GamP+GamS)*E_1000*Dt)*Kt -> 298.83583 | I13: =E13*3600*(GamP+GamS)*E_640/G13+F13*3600*(GamP+GamS)*E_1000/H13 -> 467.93298 | J13: =P_28/I13 -> 1.2309455 | K13: =P_25/I13 -> 0.76934094 | L13: =1/(E13/G13+F13/H13) -> 73.85673 | M13: =IF(L13<=60,"отличный",IF(L13<=80,"хороший",IF(L13<=100,"удовлетворительный",">100 с"))) -> хороший | N13: =H_Z2/C13 -> 50.52 | O13: =H_Z2/D13 -> 50.52
B14: справочно: 4×640 @2,5 | C14: 2.5 | D14: 2.5 | E14: 4 | F14: 0 | G14: =(2*Kv*H_Z2/C14+$F$4*INDEX(T_123,MATCH(C14,SPD,0))+(GamP+GamS)*E_640*Dt)*Kt -> 221.57019 | H14: =(2*Kv*H_Z2/D14+$F$5*INDEX(T_123,MATCH(D14,SPD,0))+(GamP+GamS)*E_1000*Dt)*Kt -> 298.83583 | I14: =E14*3600*(GamP+GamS)*E_640/G14+F14*3600*(GamP+GamS)*E_1000/H14 -> 623.91064 | J14: =P_28/I14 -> 0.92320913 | K14: =P_25/I14 -> 0.57700571 | L14: =1/(E14/G14+F14/H14) -> 55.392548 | M14: =IF(L14<=60,"отличный",IF(L14<=80,"хороший",IF(L14<=100,"удовлетворительный",">100 с"))) -> отличный | N14: =H_Z2/C14 -> 50.52 | O14: =H_Z2/D14 -> 50.52
B15: справочно: 4×1000 @3,5 (без участия 640) | C15: 3.5 | D15: 3.5 | E15: 0 | F15: 4 | G15: =(2*Kv*H_Z2/C15+$F$4*INDEX(T_123,MATCH(C15,SPD,0))+(GamP+GamS)*E_640*Dt)*Kt -> 206.00463 | H15: =(2*Kv*H_Z2/D15+$F$5*INDEX(T_123,MATCH(D15,SPD,0))+(GamP+GamS)*E_1000*Dt)*Kt -> 288.11425 | I15: =E15*3600*(GamP+GamS)*E_640/G15+F15*3600*(GamP+GamS)*E_1000/H15 -> 779.69069 | J15: =P_28/I15 -> 0.73875449 | K15: =P_25/I15 -> 0.46172156 | L15: =1/(E15/G15+F15/H15) -> 72.028563 | M15: =IF(L15<=60,"отличный",IF(L15<=80,"хороший",IF(L15<=100,"удовлетворительный",">100 с"))) -> хороший | N15: =H_Z2/C15 -> 36.085714 | O15: =H_Z2/D15 -> 36.085714

Sheet Checks
A1: ПРОВЕРКИ (TRUE — проверка пройдена; FALSE с пояснением — ожидаемая ситуация)
A3: E_640 = 8 чел. (паспортная вместимость; по формуле прил. А ГОСТ — 9 чел., см. Допущения) | B3: =E_640=8 -> TRUE
A4: E_1000 = 1000/75 (округление вниз) | B4: =E_1000=ROUNDDOWN(1000/75,0) -> TRUE
A5: Население: зона 1 + зона 2 = всего | B5: =Inputs!C21+Inputs!C22=Inputs!C13*Inputs!C20 -> TRUE
A6: Высота подъема зоны 1 = 36,6 м (+/-0,01) | B6: =ABS(H_Z1-36.6)<0.01 -> TRUE
A7: Высота подъема зоны 2 = 126,3 м (+/-0,01) | B7: =ABS(H_Z2-126.3)<0.01 -> TRUE
A8: Зона 2 (база, стр. 9: 3×640 @2,5 + 2×1000 @3,5): tи <= 50 с (ТЗ) | B8: =Zone2!L9<=TUtarget -> TRUE
A9: Зона 2 (база): Kр <= 1,0 | B9: =Zone2!J9<=1 -> TRUE
A10: Зона 1 (база, стр. 8, 2 лифта): tи <= 50 с (ТЗ) | B10: =Zone1!L8<=TUtarget -> FALSE | C10: Ожидалось FALSE: при двух лифтах целевой интервал недостижим при любой скорости; решение — третий лифт или пересмотр критерия (см. Выводы)
A11: Зона 1 (3 лифта 2×640+1×1000, 1,6 м/с): tи <= 50 с | B11: =Zone1!L11<=TUtarget -> TRUE
A12: Зона 1 (база): Kр <= 1,0 | B12: =Zone1!J8<=1 -> TRUE
A13: Зона 2 (база): H/V 1000 кг <= 40 с (прил. Б) | B13: =Zone2!O9<=40 -> TRUE
A14: Зона 2 (база): H/V 640 кг <= 40 с (прил. Б) | B14: =Zone2!N9<=40 -> FALSE | C14: Ожидалось FALSE: 640 кг @2,5 м/с вне прил. Б (для 126,3 м требуется не менее 3,2 м/с); обосновать моделированием или принять 3,5 м/с

Sheet Выводы
A1: ВЫВОДЫ И РЕКОМЕНДАЦИИ (конфигурация v5)
A3: Зона 1 (1×640 пасс. + 1×1000 пожарный, 1,6 м/с): провозная способность с запасом (Kр = 0,42 при пике 8 %), интервал 77,4 с — «хороший» уровень. Повышение скорости интервал не улучшает (малая высота подъема, доминируют остановки); целевой <= 50 с при двух лифтах недостижим.
A4: Зона 1, критерий ТЗ <= 50 с: достижим только при трех лифтах — 2×640 + 1×1000 (пожарный) при 1,6 м/с дает tи = 49,5 с (Kр = 0,29). Альтернатива — пересмотр целевого интервала на нормативный уровень «хороший» (60-80 с).
A5: Зона 2 (3×640 @2,5 + 2×1000 пожарных @3,5): провозная способность с запасом (Kр = 0,67 при пике 8 %), интервал 48,8 с <= 50 с — целевой критерий ТЗ выполнен («отличный» уровень).
A6: Скорость 3,5 м/с для лифтов 1000 кг зоны 2 — для соответствия прил. Б (H/V = 36,1 с <= 40 с). Для 640 кг зоны 2 H/V = 50,5 с превышает справочные пределы — обосновать моделированием (п. 5.2 ГОСТ Р 52941-2008) или принять 3,5/3,5 (tи = 46,5 с, полное соответствие прил. Б; кабина 640 кг на 3,5 м/с — редкое исполнение).
A7: Пожарные лифты: 3 шт. x 1000 кг (1 в зоне 1, 2 в зоне 2) — требование п. 8.1 СП 550.1311500.2026 «не менее двух» выполняется с запасом (СП 477.1325800.2020 отменен с 16.07.2026; высота здания ≈ 125 м — менее 150 м, требование «не менее трех» не применяется); в каждой зоне минимум один лифт для пожарных. При строгой трактовке «не менее двух в каждой из зон» для зоны 1 требуется второй — подтвердить при экспертизе.
A8: Критическое условие: участие лифтов для пожарных в пассажирском обслуживании в нормальном режиме (зафиксировать в ТЗ и экспликации). Без участия: зона 1 — Kр = 0,95, tи = 137,6 с; зона 2 — Kр = 1,23 (не проходит).
A9: Для кабин 640 кг: кабина с глубиной или шириной 2100 мм (перевозка на носилках, п. 5.3 ГОСТ Р 52941-2008); ширина лифтового холла не менее 2,1 м при глубине кабины 2100 мм (п. 5.13 СП 54.13330.2022).
A10: Окончательную проверку выполнить моделированием вертикального транспорта (п. 5.2 ГОСТ Р 52941-2008).
A11: Допущения, подлежащие уточнению: равномерное распределение квартир (зона 1 — 83 кв., зона 2 — 200 кв.); отметка верхнего уровня холла +6,000 м; лифты для пожарных участвуют в нормальном режиме; скорости — по подбору (зона 1 — 1,6 м/с; зона 2 — 2,5/3,5 м/с); Kt = 1,05 — нижняя граница нормативного диапазона 1,05-1,10 (п. А.2.6 г прил. А ГОСТ Р 52941-2008); при Kt = 1,10 интервалы возрастают на ~4,8 %: зона 2 — 51,1 с (за пределом целевых 50 с); Δt = 1,5 с — нижняя граница диапазона; пик — 8 % (верхняя граница ГОСТ Р 52941-2008).
A12: Проверка допущений — лист «Допущения»: ключевой риск — вместимость 640 кг (принято 8 чел., по формуле прил. А ГОСТ — 9 чел.). При E = 9 зона 2 не проходит целевой интервал 50 с (tи = 52,5 с; 3,5/3,5 — 50,6 с), зона 1 выходит из «хорошего» (81,9 с). Резерв при E = 9 — 4-й лифт 640 кг в зоне 2 (tи = 43,3 с). Обязательны моделирование и паспорт оборудования.
A13: Актуальность нормативов проверена 30.09.2026: СП 477.1325800.2020 отменен с 16.07.2026, действует СП 550.1311500.2026 (п. 8.1/8.2); ГОСТ 33984.1-2016 заменен ГОСТ 33984.1-2023 (с 01.11.2024); ГОСТ Р 51631-2008 заменен ГОСТ 33652-2019; ГОСТ 5746-2003 утратил силу в РФ — применяется ГОСТ 5746-2015. Полный перечень — лист «Нормативы».
A14: Новое требование п. 8.2 СП 550.1311500.2026: лифты, связывающие подземный паркинг с надземной частью (все лифты зон 1 и 2), должны иметь исполнение по ГОСТ Р 53296 либо выделить отдельные парковочные лифты с верхней остановкой не выше 1-го этажа — учесть в ТЗ и спецификации оборудования.

Sheet Допущения
A1: ПРОВЕРКА ДОПУЩЕНИЙ (анализ чувствительности к границам нормативных диапазонов)
A3: Допущение | B3: Нормативная основа | C3: Принято | D3: Чувствительность (к границе диапазона) | E3: Статус
A4: Население 3 чел./кв. | B4: ГОСТ Р 52941-2008: 1,2-3,0 чел./кв. | C4: Верхняя граница | D4: — | E4: Консервативно
A5: Пик 8 % | B5: ГОСТ Р 52941-2008: 4-8 %; прил. Д СП 267: 3-5 % | C5: Верхняя граница | D5: — | E5: Консервативно
A6: Kt = 1,05 | B6: Прил. А, п. А.2.6 г): 1,05-1,10 | C6: 1,05 (нижняя) | D6: 1,10 → зона 2: tи = 51,1 с (за целевыми 50 с); зона 1: 81,1 с | E6: Критично для зоны 2; подтвердить моделированием
A7: Kв = 0,8 | B7: Прил. А: 0,7-0,9 | C7: 0,8 (середина) | D7: 0,9 → зона 2: 50,8 с (за целевыми); зона 1: 79,8 с; 0,7 → 46,8 с (запас) | E7: На границе; уточнить при моделировании
A8: Δt = 1,5 с | B8: Прил. А: 1,5-2,0 с (проем < 1000 мм); 0,8-1,2 с (проем > 1000 мм) | C8: 1,5 с (нижняя для узких дверей) | D8: 2,0 → зона 2: 50,0 с (на границе); зона 1: 80,5 с. Для кабин 1000 кг с проемом > 1000 мм фактическое Δt ниже — принятая величина консервативна | E8: Приемлемо
A9: t1+t2+t3 | B9: Табл. прил. А ГОСТ Р 52941-2008 | C9: Середины диапазонов (для 3,5 и 4,0 м/с — интерполяция) | D9: — | E9: Консервативно
A10: E 640 кг = 8 чел. | B10: Прил. А: E = 640/75 = 8,53, округление до ближайшего целого → 9 чел. | C10: 8 чел. — паспортная вместимость типовой кабины 630-640 кг | D10: E = 9 → зона 2: 52,5 с (за целевыми; 3,5/3,5 — 50,6 с); зона 1: 81,9 с (2 лифта) / 53,3 с (3 лифта); Kр практически не меняется (0,67) | E10: Ключевой риск по интервалу; подтвердить паспортом лифта; при E = 9 — 4-й лифт 640 кг в зоне 2 (tи = 43,3 с)
A11: E 1000 кг = 13 чел. | B11: Прил. А: 1000/75 = 13,3 → 13 чел. | C11: 13 чел. | D11: — | E11: Совпадает с формулой ГОСТ
A12: γп = 0,8; γс = 0,4 | B12: Прил. А, п. А.2.5 (двухсторонний жилой поток) | C12: По нормативу | D12: — | E12: Соответствует нормативу
A13: P = γ·E округляется до целого | B13: Прил. А, п. А.2.6 в) | C13: 6/3 (640 кг); 10/5 (1000 кг) | D13: — | E13: Соответствует методике
A14: Интервал смешанной группы | B14: Обобщение формулы А.1.9 | C14: tи = 3600/Σ(n·3600/T) | D14: При одинаковых лифтах совпадает с А.1.9 | E14: Отразить в пояснительной записке к расчету
... A17: Наихудшая совокупность (Kt = 1,10; Kв = 0,9; Δt = 2,0; E = 9) | B17: — | C17: — | D17: Зона 2: tи = 58,4 с; зона 1 (2 лифта): 91,9 с; зона 1 (3 лифта): 59,7 с | E17: Целевые ≤ 50 с — на границе достижимого; моделирование обязательно; резерв — 4-й лифт 640 кг в зоне 2 (48,2 с)
A19: Ключевой результат: при E = 9 чел. для 640 кг (по формуле прил. А ГОСТ Р 52941-2008) зона 2 не проходит целевой интервал ≤ 50 с, зона 1 выходит из уровня «хороший». Принятые значения — в границах нормативных диапазонов, однако целевой интервал достигается на совокупности принятых значений: обязательны моделирование (п. 5.2 ГОСТ Р 52941-2008) и подтверждение вместимостей паспортом оборудования.

Sheet Нормативы
A1: ПЕРЕЧЕНЬ ИСПОЛЬЗУЕМЫХ НОРМАТИВНЫХ ДОКУМЕНТОВ (статусы проверены на 30.09.2026)
A3: Обозначение | B3: Наименование | C3: Статус на 30.09.2026 | D3: Применение в расчете
A4: ГОСТ Р 52941-2008 (ИСО 4190-6:1984) | B4: Лифты пассажирские. Проектирование систем вертикального транспорта в жилых зданиях | C4: Действует (каталог Росстандарта; данные актуализированы 03.08.2026) | D4: Основной норматив: методика расчета (прил. А), уровни комфортности (разд. 5), требования к кабинетам (п. 5.3), H/V (прил. Б), моделирование (п. 5.2)
A5: СП 550.1311500.2026 | B5: Здания высотные. Требования пожарной безопасности | C5: Действует с 01.06.2026 (приказ МЧС России от 26.02.2026 № 137; взамен СП 477.1325800.2020, отмененного с 16.07.2026) | D5: Требования к лифтовому оборудованию (разд. 8): не менее двух лифтов для пожарных (при зонной схеме — в каждой из зоне), ГП не менее 1000 кг, обособленные шахты; связь подземной и надземной частей (п. 8.2); огнестойкость шахт (табл. 6.1)
A6: СП 54.13330.2022 | B6: Здания жилые многоквартирные (СНиП 31-01-2003) | C6: Действует (с Изм. № 1 от 19.09.2024 № 630/пр, Изм. № 2 от 27.12.2024 № 938/пр) | D6: Ширина лифтовых холлов (п. 5.13); минимальное число лифтов (прил. В)
A7: СП 267.1325800.2016 | B7: Здания и комплексы высотные. Правила проектирования | C7: Действует (с Изм. № 1 от 30.12.2020 № 918/пр, Изм. № 2 от 27.12.2024 № 951/пр, Изм. № 3; ред. с 28.01.2025) | D7: Применимость при высоте более 75 м; зонная схема лифтов (п. 10.8.1.3 с Изм. № 1); пассажиропотоки (прил. Д)
A8: ГОСТ 33984.1-2023 | B8: Лифты. Лифты для транспортирования людей или людей и грузов. Общие требования безопасности к устройству и установке | C8: Действует с 01.11.2024 (взамен ГОСТ 33984.1-2016 (EN 81-20:2014); приказ Росстандарта от 08.11.2023 № 1352-ст) | D8: Общие требования безопасности к пассажирским лифтам
A9: ГОСТ 34305-2017 (EN 81-72:2015) | B9: Лифты пассажирские. Лифты для пожарных | C9: Действует с 01.03.2019 (приказ Росстандарта от 25.09.2018 № 649-ст; взамен отмененного с 15.02.2020 ГОСТ Р 52382-2010) | D9: Требования к лифтам для пожарных (в т.ч. скорость доставки пожарных на верхний этаж не более 60 с — п. 5.2.3)
A10: ГОСТ Р 53296-2009 | B10: Установка лифтов для пожарных в зданиях и сооружениях. Требования пожарной безопасности | C10: Действует (в разработке Изм. № 1 — ВНИИПО МЧС России) | D10: Требования к установке лифтов для пожарных; ссылочный норматив СП 550 (п. 8.1, 8.2)
A11: ГОСТ 5746-2015 (ISO 4190-1:2010) | B11: Лифты пассажирские. Основные параметры и размеры | C11: Действует в РФ (ГОСТ 5746-2003 утратил силу в РФ с 01.06.2010) | D11: Параметры и размеры пассажирских лифтов; ссылочный норматив ГОСТ Р 52941-2008 и ГОСТ 34305-2017
A12: ГОСТ 33652-2019 (EN 81-70:2018) | B12: Лифты. Специальные требования безопасности и доступности для инвалидов и других маломобильных групп населения | C12: Действует (взамен ГОСТ Р 51631-2008 с 01.01.2017 и ГОСТ 33652-2015 с 01.06.2020) | D12: Доступность пассажирских лифтов для МГН (кабины 2100 мм)
A13: СП 59.13330.2020 | B13: Доступность зданий и сооружений для маломобильных групп населения (СНиП 35-01-2001) | C13: Действует (с Изм. № 1-4: 31.05.2022 № 434/пр; 21.11.2023 № 833/пр; 19.09.2024 № 630/пр; 27.12.2024 № 938/пр) | D13: Доступность здания и лифтового узла для МГН
A15: В расчете не применяются отмененные документы: СП 477.1325800.2020 (отменен с 16.07.2026), ГОСТ 33984.1-2016, ГОСТ Р 51631-2008, ГОСТ 33652-2015, ГОСТ Р 52382-2010, ГОСТ 5746-2003 (утратил силу в РФ с 01.06.2010). Их положения учтены через действующие документы-замены.
